<?xml version="1.0" ?>
<robot name="ROBOT" xmlns:xacro="http://www.ros.org/wiki/xacro">

<xacro:include filename="$(find ROBOT_description)/urdf/materials.xacro" />
<xacro:include filename="$(find ROBOT_description)/urdf/ROBOT.trans" />
<xacro:include filename="$(find ROBOT_description)/urdf/ROBOT.gazebo" />
<link name="base_link">
  <inertial>
    <origin xyz="3.465925149719148e-14 0.004492444103832285 0.05429246005931272" rpy="0 0 0"/>
    <mass value="4.581769035764288"/>
    <inertia ixx="0.026764" iyy="0.024908" izz="0.047599" ixy="0.0" iyz="-0.000872" ixz="0.0"/>
  </inertial>
  <visual>
    <origin xyz="0 0 0" rpy="0 0 0"/>
    <geometry>
      <mesh filename="package://ROBOT_description/meshes/base_link.stl" scale="0.001 0.001 0.001"/>
    </geometry>
    <material name="silver"/>
  </visual>
  <collision>
    <origin xyz="0 0 0" rpy="0 0 0"/>
    <geometry>
      <mesh filename="package://ROBOT_description/meshes/base_link.stl" scale="0.001 0.001 0.001"/>
    </geometry>
  </collision>
</link>

<link name="right_wheel_1">
  <inertial>
    <origin xyz="-0.017499999999999988 -8.271461571602899e-18 0.0" rpy="0 0 0"/>
    <mass value="0.2556471021858694"/>
    <inertia ixx="0.00032" iyy="0.000186" izz="0.000186" ixy="0.0" iyz="-0.0" ixz="0.0"/>
  </inertial>
  <visual>
    <origin xyz="0.125 -0.0 -0.0525" rpy="0 0 0"/>
    <geometry>
      <mesh filename="package://ROBOT_description/meshes/right_wheel_1.stl" scale="0.001 0.001 0.001"/>
    </geometry>
    <material name="silver"/>
  </visual>
  <collision>
    <origin xyz="0.125 -0.0 -0.0525" rpy="0 0 0"/>
    <geometry>
      <mesh filename="package://ROBOT_description/meshes/right_wheel_1.stl" scale="0.001 0.001 0.001"/>
    </geometry>
  </collision>
</link>

<link name="left_wheel_1">
  <inertial>
    <origin xyz="0.017499999999999988 -8.271461571602899e-18 -6.938893903907228e-18" rpy="0 0 0"/>
    <mass value="0.2556471021858694"/>
    <inertia ixx="0.00032" iyy="0.000186" izz="0.000186" ixy="0.0" iyz="-0.0" ixz="-0.0"/>
  </inertial>
  <visual>
    <origin xyz="-0.125 -0.0 -0.0525" rpy="0 0 0"/>
    <geometry>
      <mesh filename="package://ROBOT_description/meshes/left_wheel_1.stl" scale="0.001 0.001 0.001"/>
    </geometry>
    <material name="silver"/>
  </visual>
  <collision>
    <origin xyz="-0.125 -0.0 -0.0525" rpy="0 0 0"/>
    <geometry>
      <mesh filename="package://ROBOT_description/meshes/left_wheel_1.stl" scale="0.001 0.001 0.001"/>
    </geometry>
  </collision>
</link>

<link name="lidar_1">
  <inertial>
    <origin xyz="0.0 0.0 0.015" rpy="0 0 0"/>
    <mass value="0.13185853415738905"/>
    <inertia ixx="3.5e-05" iyy="3.5e-05" izz="5e-05" ixy="-0.0" iyz="-0.0" ixz="0.0"/>
  </inertial>
  <visual>
    <origin xyz="-0.0 -0.09 -0.115" rpy="0 0 0"/>
    <geometry>
      <mesh filename="package://ROBOT_description/meshes/lidar_1.stl" scale="0.001 0.001 0.001"/>
    </geometry>
    <material name="silver"/>
  </visual>
  <collision>
    <origin xyz="-0.0 -0.09 -0.115" rpy="0 0 0"/>
    <geometry>
      <mesh filename="package://ROBOT_description/meshes/lidar_1.stl" scale="0.001 0.001 0.001"/>
    </geometry>
  </collision>
</link>

<joint name="Rev1" type="continuous">
  <origin xyz="-0.125 0.0 0.0525" rpy="0 0 0"/>
  <parent link="base_link"/>
  <child link="right_wheel_1"/>
  <axis xyz="-1.0 0.0 0.0"/>
</joint>

<joint name="Rev2" type="continuous">
  <origin xyz="0.125 0.0 0.0525" rpy="0 0 0"/>
  <parent link="base_link"/>
  <child link="left_wheel_1"/>
  <axis xyz="1.0 0.0 0.0"/>
</joint>

<joint name="Rigid3" type="fixed">
  <origin xyz="0.0 0.09 0.115" rpy="0 0 0"/>
  <parent link="base_link"/>
  <child link="lidar_1"/>
</joint>

</robot>
